import qs from "qs";
import * as auth from "auth.provider";
import { useAuth } from "context/auth-context";
const apiUrl = process.env.REACT_APP_API_URL;

interface Config extends RequestInit {
  token?: string;
  data?: object;
}

export const http = async (
  endpoint: string,
  { data, token, headers, ...customConfig }: Config = {}
) => {
  const config = {
    method: "GET",
    headers: {
      Authorization: token ? `Bearer ${token}` : "",
      "Content-Type": data ? "application/json" : "",
    },
    ...customConfig,
  };

  if (config.method.toUpperCase() === "GET") {
    endpoint += `?${qs.stringify(data)}`;
  } else {
    config.body = JSON.stringify(data || {});
  }

  return window
    .fetch(`${apiUrl}/${endpoint}`, config)
    .then(async (response) => {
      if (response.status === 401) {
        await auth.logout();
        window.location.reload();
        return Promise.reject({ message: "请重新登录" });
      }
      const data = await response.json();
      if (response.ok) {
        return data;
      } else {
        // 这里手动抛出异常是因为fetch在401 500 的时候是不会抛出异常的，而axios的表现不同，401 500的情况下会抛出异常
        return Promise.reject(data);
      }
    });
};

export const useHttp = () => {
  const { user } = useAuth();
  return (...[endpoint, config]: Parameters<typeof http>) =>
    http(endpoint, { ...config, token: user?.token });
};
